Traceback (most recent call last):
  File "/opt/hostedtoolcache/Python/3.7.12/x64/lib/python3.7/site-packages/jupyter_cache/executors/utils.py", line 56, in single_nb_execution
    record_timing=False,
  File "/opt/hostedtoolcache/Python/3.7.12/x64/lib/python3.7/site-packages/nbclient/client.py", line 1093, in execute
    return NotebookClient(nb=nb, resources=resources, km=km, **kwargs).execute()
  File "/opt/hostedtoolcache/Python/3.7.12/x64/lib/python3.7/site-packages/nbclient/util.py", line 84, in wrapped
    return just_run(coro(*args, **kwargs))
  File "/opt/hostedtoolcache/Python/3.7.12/x64/lib/python3.7/site-packages/nbclient/util.py", line 62, in just_run
    return loop.run_until_complete(coro)
  File "/opt/hostedtoolcache/Python/3.7.12/x64/lib/python3.7/asyncio/base_events.py", line 587, in run_until_complete
    return future.result()
  File "/opt/hostedtoolcache/Python/3.7.12/x64/lib/python3.7/site-packages/nbclient/client.py", line 560, in async_execute
    cell, index, execution_count=self.code_cells_executed + 1
  File "/opt/hostedtoolcache/Python/3.7.12/x64/lib/python3.7/site-packages/nbclient/client.py", line 854, in async_execute_cell
    self._check_raise_for_error(cell, exec_reply)
  File "/opt/hostedtoolcache/Python/3.7.12/x64/lib/python3.7/site-packages/nbclient/client.py", line 756, in _check_raise_for_error
    raise CellExecutionError.from_cell_and_msg(cell, exec_reply_content)
nbclient.exceptions.CellExecutionError: An error occurred while executing the following cell:
------------------
user_artists = pd.read_csv('data/user_artists.dat', sep='\t')
user_friendships =  pd.read_csv('data/unqiue_friendships.csv')
tags = pd.read_csv(open('data/tags.dat', errors='replace'), sep='\t')
user_taggedartists = pd.read_csv(r'data/user_taggedartists-timestamps.dat', sep='\t')
user_taggedartists = pd.merge(user_taggedartists, tags, on=['tagID'])
tags = pd.read_csv(open('data/tags.dat', errors='replace'), sep='\t')

------------------

[0;31m---------------------------------------------------------------------------[0m
[0;31mNameError[0m                                 Traceback (most recent call last)
[0;32m/tmp/ipykernel_2753/2131395244.py[0m in [0;36m<module>[0;34m[0m
[0;32m----> 1[0;31m [0muser_artists[0m [0;34m=[0m [0mpd[0m[0;34m.[0m[0mread_csv[0m[0;34m([0m[0;34m'data/user_artists.dat'[0m[0;34m,[0m [0msep[0m[0;34m=[0m[0;34m'\t'[0m[0;34m)[0m[0;34m[0m[0;34m[0m[0m
[0m[1;32m      2[0m [0muser_friendships[0m [0;34m=[0m  [0mpd[0m[0;34m.[0m[0mread_csv[0m[0;34m([0m[0;34m'data/unqiue_friendships.csv'[0m[0;34m)[0m[0;34m[0m[0;34m[0m[0m
[1;32m      3[0m [0mtags[0m [0;34m=[0m [0mpd[0m[0;34m.[0m[0mread_csv[0m[0;34m([0m[0mopen[0m[0;34m([0m[0;34m'data/tags.dat'[0m[0;34m,[0m [0merrors[0m[0;34m=[0m[0;34m'replace'[0m[0;34m)[0m[0;34m,[0m [0msep[0m[0;34m=[0m[0;34m'\t'[0m[0;34m)[0m[0;34m[0m[0;34m[0m[0m
[1;32m      4[0m [0muser_taggedartists[0m [0;34m=[0m [0mpd[0m[0;34m.[0m[0mread_csv[0m[0;34m([0m[0;34mr'data/user_taggedartists-timestamps.dat'[0m[0;34m,[0m [0msep[0m[0;34m=[0m[0;34m'\t'[0m[0;34m)[0m[0;34m[0m[0;34m[0m[0m
[1;32m      5[0m [0muser_taggedartists[0m [0;34m=[0m [0mpd[0m[0;34m.[0m[0mmerge[0m[0;34m([0m[0muser_taggedartists[0m[0;34m,[0m [0mtags[0m[0;34m,[0m [0mon[0m[0;34m=[0m[0;34m[[0m[0;34m'tagID'[0m[0;34m][0m[0;34m)[0m[0;34m[0m[0;34m[0m[0m

[0;31mNameError[0m: name 'pd' is not defined
NameError: name 'pd' is not defined

